{"id": "CVE-2009-5010", "sourceIdentifier": "cve@mitre.org", "published": "2010-10-19T20:00:02.957", "lastModified": "2010-10-20T04:00:00.000", "vulnStatus": "Analyzed", "cveTags": [], "descriptions": [{"lang": "en", "value": "Race condition in the FTPHandler class in ftpserver.py in pyftpdlib before 0.5.1 allows remote attackers to cause a denial of service (daemon outage) by establishing and then immediately closing a TCP connection, leading to the accept function having an unexpected return value of None, a different vulnerability than CVE-2010-3494."}, {"lang": "es", "value": "Condici\u00f3n de carrera en la clase FTPHandler en ftpserver.py de pyftpdlib anterior a v0.5.1 permite a atacantes remotos provocar una denegaci\u00f3n de servicio (ca\u00edda del demonio) estableciendo y cerrando inmediatamente una conexi\u00f3n TCP, provocando que la funci\u00f3n Accept tenga un valor de retorno no esperado de None. Una vulnerabilidad diferente de CVE-2010-3494"}], "metrics": {"cvssMetricV2": [{"source": "nvd@nist.gov", "type": "Primary", "cvssData": {"version": "2.0", "vectorString": "AV:N/AC:M/Au:N/C:N/I:N/A:P", "accessVector": "NETWORK", "accessComplexity": "MEDIUM", "authentication": "NONE", "confidentialityImpact": "NONE", "integrityImpact": "NONE", "availabilityImpact": "PARTIAL", "baseScore": 4.3}, "baseSeverity": "MEDIUM", "exploitabilityScore": 8.6, "impactScore": 2.9, "acInsufInfo": false, "obtainAllPrivilege": false, "obtainUserPrivilege": false, "obtainOtherPrivilege": false, "userInteractionRequired": false}]}, "weaknesses": [{"source": "nvd@nist.gov", "type": "Primary", "description": [{"lang": "en", "value": "CWE-362"}]}], "configurations": [{"nodes": [{"operator": "OR", "negate": false, "cpeMatch": [{"vulnerable": true, "criteria": "cpe:2.3:a:g.rodola:pyftpdlib:*:*:*:*:*:*:*:*", "versionEndIncluding": "0.5.0", "matchCriteriaId": "5443E1F4-F425-4232-9707-ABC45DA93719"}, {"vulnerable": true, "criteria": "cpe:2.3:a:g.rodola:pyftpdlib:0.1:*:*:*:*:*:*:*", "matchCriteriaId": "DB3D49FE-C51B-49E8-895E-AD4C4E138425"}, {"vulnerable": true, "criteria": "cpe:2.3:a:g.rodola:pyftpdlib:0.1.1:*:*:*:*:*:*:*", "matchCriteriaId": "E2B112CF-87F7-4A6A-9D75-AD6A577FB979"}, {"vulnerable": true, "criteria": "cpe:2.3:a:g.rodola:pyftpdlib:0.2.0:*:*:*:*:*:*:*", "matchCriteriaId": "73F985FF-9073-42E5-8651-7A440C1453E2"}, {"vulnerable": true, "criteria": "cpe:2.3:a:g.rodola:pyftpdlib:0.3.0:*:*:*:*:*:*:*", "matchCriteriaId": "DA58DF28-E4B7-4BD6-B77C-56521DE0CE4F"}, {"vulnerable": true, "criteria": "cpe:2.3:a:g.rodola:pyftpdlib:0.4.0:*:*:*:*:*:*:*", "matchCriteriaId": "63AAA8E0-D608-45CD-B46C-C8936607E525"}]}]}], "references": [{"url": "http://bugs.python.org/issue6706", "source": "cve@mitre.org", "tags": ["Patch"]}, {"url": "http://code.google.com/p/pyftpdlib/issues/detail?id=91", "source": "cve@mitre.org"}, {"url": "http://code.google.com/p/pyftpdlib/source/browse/trunk/HISTORY", "source": "cve@mitre.org"}, {"url": "http://code.google.com/p/pyftpdlib/source/detail?r=439", "source": "cve@mitre.org"}, {"url": "http://code.google.com/p/pyftpdlib/source/diff?spec=svn439&r=439&format=side&path=/trunk/pyftpdlib/ftpserver.py", "source": "cve@mitre.org"}, {"url": "http://www.openwall.com/lists/oss-security/2010/09/09/6", "source": "cve@mitre.org"}, {"url": "http://www.openwall.com/lists/oss-security/2010/09/11/2", "source": "cve@mitre.org"}, {"url": "http://www.openwall.com/lists/oss-security/2010/09/22/3", "source": "cve@mitre.org"}, {"url": "http://www.openwall.com/lists/oss-security/2010/09/24/3", "source": "cve@mitre.org"}, {"url": "https://bugs.launchpad.net/zodb/+bug/135108", "source": "cve@mitre.org"}], "techniques": [{"techniqueID": "T1210", "comment": "CVE-2009-5010 - This vulnerability allows an attacker to cause a denial of service (daemon outage) by establishing and then immediately closing a TCP connection, leading to the accept function having an unexpected return value of None."}, {"techniqueID": "T1547.001", "comment": "CVE-2009-5010 - This vulnerability could be used to carry out a race condition attack, allowing an attacker to exploit the unexpected accept function return value and compromise the system."}], "stix_bundle": {"type": "bundle", "id": "https://example.com/bundle/CVE-2009-5010", "title": "CVE-2009-5010 Bundle", "description": "STIX 2.1 bundle for CVE-2009-5010", "objects": {"vulnerability": {"type": "vulnerability", "id": "https://cve.mitre.org/cgi-bin/cvename.cgi?name=CVE-2009-5010", "title": "FTPHandler race condition", "description": "A race condition in the FTPHandler class in ftpserver.py in pyftpdlib before 0.5.1 allows remote attackers to cause a denial of service (daemon outage) by establishing and then immediately closing a TCP connection, leading to the accept function having an unexpected return value of None.", "severity": "MEDIUM", "cvss": {"configuration": {"vectorString": "AV:N/AC:M/Au:N/C:N/I:N/A:P", "baseSeverity": "MEDIUM", "baseScore": 4.3}}}, "threat.actor": {"type": "actor", "id": "https://cve.mitre.org/cgi-bin/cvename.cgi?name=CVE-2009-5010", "name": "Malicious actor", "description": "An attacker who can exploits the race condition vulnerability"}}, "relationships": [{"type": "related-to", "id": "https://cve.mitre.org/cgi-bin/cvename.cgi?name=CVE-2009-5010", "object_id": "https://example.com/technique/T1210", "relationship": "exploits"}, {"type": "related-to", "id": "https://cve.mitre.org/cgi-bin/cvename.cgi?name=CVE-2009-5010", "object_id": "https://example.com/technique/T1547.001", "relationship": "exploits"}]}, "technical_analysis": {"Introduction": "The CVE-2009-5010 vulnerability in pyftpdlib is a race condition attack that allows an attacker to cause a denial of service (daemon outage) by establishing and then immediately closing a TCP connection.", "Impact and Scope": "The impact of this vulnerability is a denial of service (daemon outage), and the scope is remote attackers who can exploit the race condition.", "Related MITRE ATT&CK Techniques": "The vulnerability is related to T1210 and T1547.001, which are both race condition techniques.", "Technical Details": "The race condition occurs when the accept function is called with an unexpected return value of None, which can be triggered by establishing and then immediately closing a TCP connection.", "Detection": "Detection methods include monitoring for unusual network traffic patterns and checking for kernel-level errors.", "Mitigation": "Mitigation strategies include disabling the vulnerable FTP server, updating to a patched version of pyftpdlib, and implementing firewall rules to block the exploit.", "Conclusion": "In conclusion, the CVE-2009-5010 vulnerability is a race condition attack that can cause a denial of service (daemon outage) and is related to T1210 and T1547.001."}, "executive_analysis": {"Overview": "The CVE-2009-5010 vulnerability in pyftpdlib is a race condition attack that can cause a denial of service (daemon outage) and has a medium severity rating.", "Business Impact": "The business impact of this vulnerability includes potential downtime and lost productivity.", "Technical Impact": "The technical impact includes potentially compromised system security and the need for system downtime.", "Mitigation Strategies": "Mitigation strategies include disabling the vulnerable FTP server, updating to a patched version of pyftpdlib, and implementing firewall rules to block the exploit.", "Recommendations": "Recommendations include patching immediately, disabling the vulnerable FTP server, and implementing firewall rules to block the exploit.", "Conclusions": "In conclusion, executives should prioritize patching and mitigation strategies to minimize the impact of this vulnerability."}}